# Урок 8: Обработка ошибок в Kotlin

## Введение

Обработка ошибок является важной частью разработки надежного программного обеспечения. Kotlin предлагает несколько механизмов для эффективной обработки ошибок, включая традиционные исключения, а также более современные подходы, такие как тип `Result` и null-безопасность.

В этом уроке мы рассмотрим различные способы обработки ошибок в Kotlin, их преимущества и недостатки, а также лучшие практики их применения.

## Исключения в Kotlin

### Основы исключений

Исключения (exceptions) в Kotlin работают аналогично другим языкам программирования, таким как Java. Исключение — это объект, который представляет ошибку или необычную ситуацию, возникшую во время выполнения программы.

```kotlin
fun divide(a: Int, b: Int): Int {
    if (b == 0) {
        throw ArithmeticException("Деление на ноль")
    }
    return a / b
}
```

### Иерархия исключений

Kotlin использует ту же иерархию исключений, что и Java:

- `Throwable` — базовый класс для всех исключений
  - `Error` — серьезные ошибки, обычно не обрабатываемые приложением (например, `OutOfMemoryError`)
  - `Exception` — исключения, которые приложение может обработать
    - `RuntimeException` — исключения, которые не требуют явного объявления (например, `NullPointerException`, `ArithmeticException`)
    - Другие исключения, требующие явного объявления в Java (например, `IOException`)

В Kotlin, в отличие от Java, все исключения являются необрабатываемыми (unchecked), то есть компилятор не требует их явного объявления или обработки.

### Блок try-catch-finally

Для обработки исключений в Kotlin используется блок `try-catch-finally`:

```kotlin
fun readFile(path: String): String {
    try {
        // Код, который может вызвать исключение
        val file = File(path)
        return file.readText()
    } catch (e: FileNotFoundException) {
        // Обработка конкретного исключения
        println("Файл не найден: ${e.message}")
        return ""
    } catch (e: IOException) {
        // Обработка другого исключения
        println("Ошибка ввода-вывода: ${e.message}")
        return ""
    } finally {
        // Код, который выполнится в любом случае
        println("Операция чтения файла завершена")
    }
}
```

### try как выражение

В Kotlin блок `try` является выражением, то есть может возвращать значение:

```kotlin
val result = try {
    divide(10, 0)
} catch (e: ArithmeticException) {
    0 // Значение по умолчанию в случае ошибки
}

println(result) // Выведет: 0
```

### Создание собственных исключений

Вы можете создавать собственные классы исключений, наследуясь от `Exception` или его подклассов:

```kotlin
class InvalidAgeException(message: String) : Exception(message)

fun validateAge(age: Int) {
    if (age < 0) {
        throw InvalidAgeException("Возраст не может быть отрицательным")
    }
    if (age > 150) {
        throw InvalidAgeException("Возраст не может быть больше 150")
    }
    println("Возраст $age валиден")
}
```

## Функция use для автоматического закрытия ресурсов

Kotlin предоставляет функцию `use`, которая автоматически закрывает ресурсы, реализующие интерфейс `Closeable` или `AutoCloseable`, даже если возникло исключение:

```kotlin
fun readFileContents(path: String): String {
    File(path).bufferedReader().use { reader ->
        return reader.readText()
    }
}
```

Это эквивалентно следующему коду с блоком `try-finally`:

```kotlin
fun readFileContents(path: String): String {
    val reader = File(path).bufferedReader()
    try {
        return reader.readText()
    } finally {
        reader.close()
    }
}
```

## Класс Result

Начиная с Kotlin 1.3, стандартная библиотека включает класс `Result`, который представляет результат операции, которая может завершиться успешно или с ошибкой:

```kotlin
fun divideWithResult(a: Int, b: Int): Result<Int> {
    return try {
        Result.success(a / b)
    } catch (e: ArithmeticException) {
        Result.failure(e)
    }
}
```

### Использование Result

```kotlin
// Получение результата
val result = divideWithResult(10, 2)

// Проверка успешности
if (result.isSuccess) {
    println("Результат: ${result.getOrNull()}")
} else {
    println("Ошибка: ${result.exceptionOrNull()?.message}")
}

// Получение значения или значения по умолчанию
val value = result.getOrDefault(0)

// Получение значения или выброс исключения
val valueOrThrow = result.getOrThrow()

// Преобразование результата
val mappedResult = result.map { it * 2 }

// Обработка ошибки
val recoveredResult = result.recover { 0 }
```

### Функция runCatching

Kotlin также предоставляет функцию `runCatching`, которая упрощает создание объектов `Result`:

```kotlin
val result = runCatching {
    divide(10, 0)
}

// Обработка результата с помощью функций-расширений
result
    .onSuccess { println("Результат: $it") }
    .onFailure { println("Ошибка: ${it.message}") }
```

### Цепочки операций с Result

Класс `Result` позволяет создавать цепочки операций, обрабатывая успешные результаты и ошибки:

```kotlin
fun fetchUser(userId: String): Result<User> {
    // Получение пользователя из базы данных
}

fun fetchUserData(user: User): Result<UserData> {
    // Получение данных пользователя
}

fun processUserData(userId: String): Result<ProcessedData> {
    return fetchUser(userId)
        .flatMap { user -> fetchUserData(user) }
        .map { userData -> processData(userData) }
        .recover { error -> 
            when (error) {
                is UserNotFoundException -> ProcessedData.empty()
                else -> throw error
            }
        }
}
```

## Null-безопасность как механизм обработки ошибок

Одной из ключевых особенностей Kotlin является встроенная защита от null-ссылок, которая может рассматриваться как механизм обработки ошибок на уровне типов.

### Nullable типы

```kotlin
// Переменная может содержать null
var name: String? = "Kotlin"
name = null // Допустимо

// Переменная не может содержать null
var nonNullName: String = "Kotlin"
// nonNullName = null // Ошибка компиляции
```

### Безопасный вызов оператора (?.)

```kotlin
val length = name?.length // Если name равно null, то length тоже будет null
```

### Оператор Elvis (?:)

```kotlin
val length = name?.length ?: 0 // Если name?.length равно null, то length будет 0
```

### Оператор !! (Not-null assertion)

```kotlin
val length = name!!.length // Если name равно null, будет выброшено исключение NullPointerException
```

### Проверка на null с помощью if

```kotlin
val length = if (name != null) name.length else 0
```

### Функция let

```kotlin
name?.let {
    println("Имя: $it, длина: ${it.length}")
}
```

## Сравнение подходов к обработке ошибок

### Исключения vs Result vs Null-безопасность

| Подход | Преимущества | Недостатки |
|--------|--------------|------------|
| Исключения | - Стандартный механизм<br>- Хорошо подходит для непредвиденных ошибок<br>- Подробная информация об ошибке | - Нарушают поток выполнения<br>- Могут быть пропущены<br>- Производительность |
| Result | - Явное представление ошибок<br>- Функциональный подход<br>- Цепочки операций | - Дополнительная обертка<br>- Относительно новый API |
| Null-безопасность | - Встроена в систему типов<br>- Предотвращает ошибки на этапе компиляции<br>- Лаконичный синтаксис | - Ограниченная информация об ошибке<br>- Подходит не для всех случаев |

### Когда использовать каждый подход

- **Исключения**: для непредвиденных ошибок, которые не должны возникать при нормальной работе программы (например, ошибки ввода-вывода, неверный формат данных).
- **Result**: для операций, которые могут завершиться ошибкой в нормальных условиях (например, сетевые запросы, парсинг данных).
- **Null-безопасность**: для представления отсутствия значения или необязательных значений.

## Практические примеры

### Пример 1: Парсинг числа

```kotlin
fun parseIntSafely(input: String): Int? {
    return try {
        input.toInt()
    } catch (e: NumberFormatException) {
        null
    }
}

// Использование
val number1 = parseIntSafely("42") // 42
val number2 = parseIntSafely("abc") // null

// Обработка результата
number1?.let { println("Число: $it") }
number2?.let { println("Число: $it") } // Не выполнится
```

### Пример 2: Чтение файла с использованием Result

```kotlin
fun readFileContent(path: String): Result<String> {
    return runCatching {
        File(path).readText()
    }
}

// Использование
val content = readFileContent("config.txt")
    .onSuccess { println("Содержимое файла: $it") }
    .onFailure { println("Ошибка чтения файла: ${it.message}") }
    .getOrDefault("Файл не найден")
```

### Пример 3: Безопасная цепочка вызовов

```kotlin
data class Address(val street: String?, val city: String?, val zipCode: String?)
data class User(val name: String, val address: Address?)
data class Company(val name: String, val owner: User?)

fun getZipCode(company: Company?): String {
    return company?.owner?.address?.zipCode ?: "Неизвестный индекс"
}

// Использование
val address = Address("Ленина 1", "Москва", "123456")
val user = User("Иван", address)
val company = Company("ООО Рога и Копыта", user)

println(getZipCode(company)) // "123456"
println(getZipCode(null)) // "Неизвестный индекс"
```

### Пример 4: Комбинирование подходов

```kotlin
fun divideAndProcess(a: Int, b: Int): Result<Int> {
    // Проверка на null с помощью оператора Elvis
    val divisor = b.takeIf { it != 0 } ?: return Result.failure(ArithmeticException("Деление на ноль"))
    
    // Использование try-catch внутри runCatching
    return runCatching {
        val result = a / divisor
        
        // Дополнительная проверка результата
        if (result < 0) {
            throw IllegalStateException("Отрицательный результат")
        }
        
        result
    }
}

// Использование
divideAndProcess(10, 2)
    .onSuccess { println("Результат: $it") }
    .onFailure { println("Ошибка: ${it.message}") }

divideAndProcess(10, 0)
    .onSuccess { println("Результат: $it") }
    .onFailure { println("Ошибка: ${it.message}") }
```

## Лучшие практики обработки ошибок в Kotlin

1. **Предпочитайте null-безопасность** для представления отсутствия значения.
2. **Используйте Result** для операций, которые могут завершиться ошибкой в нормальных условиях.
3. **Используйте исключения** для непредвиденных ошибок или нарушений инвариантов.
4. **Создавайте специфические исключения** для различных типов ошибок.
5. **Используйте функцию use** для автоматического закрытия ресурсов.
6. **Избегайте пустых блоков catch**, всегда обрабатывайте или регистрируйте исключения.
7. **Предпочитайте функциональный подход** с использованием `runCatching`, `map`, `flatMap` и `recover`.
8. **Документируйте возможные исключения** в комментариях KDoc.

## Заключение

Kotlin предоставляет несколько механизмов для обработки ошибок, каждый из которых имеет свои преимущества и недостатки. Выбор подходящего механизма зависит от конкретной ситуации и требований приложения.

Ключевые особенности обработки ошибок в Kotlin:
- Все исключения являются необрабатываемыми (unchecked)
- Блок `try` является выражением и может возвращать значение
- Функция `use` для автоматического закрытия ресурсов
- Класс `Result` для функционального подхода к обработке ошибок
- Встроенная null-безопасность для предотвращения NullPointerException

Эффективное использование этих механизмов позволяет создавать более надежный и поддерживаемый код. 